Workbook

Sheet Raw_Data
A1: Employee_ID | B1: First_Name | C1: Last_Name | D1: Full_Name | E1: Email | F1: Department | G1: Job_Title | H1: City | I1: State | J1: Work_Mode | K1: Employment_Type | L1: Joining_Year | M1: Experience_Years | N1: Annual_Salary | O1: Bonus_Percentage | P1: Bonus_Amount | Q1: Performance_Score | R1: Performance_Rating | S1: Status | T1: Education | U1: Skills | V1: Projects_Count | W1: Leave_Balance_Days
A2: 1001 | B2: Arun | C2: Kumar | D2: Arun Kumar | E2: arun.kumar@example.com | F2: IT | G2: Data Engineer | H2: Chennai | I2: Tamil Nadu | J2: Hybrid | K2: Full-Time | L2: 2019 | M2: 7 | N2: 65000 | O2: 12 | P2: 7800 | Q2: 88 | R2: Good | S2: Active | T2: B.Tech | U2: Python;SQL;Cloud;Git;Spark | V2: 2 | W2: 12
A3: 1002 | B3: Priya | C3: Sharma | D3: Priya Sharma | E3: priya.sharma@example.com | F3: HR | G3: HR Manager | H3: Bengaluru | I3: Karnataka | J3: Hybrid | K3: Full-Time | L3: 2018 | M3: 8 | N3: 75000 | O3: 15 | P3: 11250 | Q3: 92 | R3: Excellent | S3: Active | T3: MBA | U3: Recruitment;Excel;HRIS;Communication | V3: 5 | W3: 8
A4: 1003 | B4: David | C4: Wilson | D4: David Wilson | E4: david.wilson@example.com | F4: IT | G4: Senior Data Engineer | H4: Chennai | I4: Tamil Nadu | J4: Remote | K4: Full-Time | L4: 2017 | M4: 9 | N4: 90000 | O4: 15 | P4: 13500 | Q4: 95 | R4: Excellent | S4: Active | T4: B.Tech | U4: Python;SQL;Cloud;Git;Spark | V4: 7 | W4: 10
A5: 1004 | B5: Meena | C5: Ravi | D5: Meena Ravi | E5: meena.ravi@example.com | F5: Finance | G5: Financial Analyst | H5: Hyderabad | I5: Telangana | J5: Office | K5: Full-Time | L5: 2020 | M5: 6 | N5: 65000 | O5: 8 | P5: 5200 | Q5: 78 | R5: Average | S5: Active | T5: M.Com | U5: Excel;Accounting;Power BI;Financial Analysis | V5: 3 | W5: 15
A6: 1005 | B6: Rahul | C6: Verma | D6: Rahul Verma | E6: rahul.verma@example.com | F6: IT | G6: Cloud Engineer | H6: Bengaluru | I6: Karnataka | J6: Hybrid | K6: Full-Time | L6: 2016 | M6: 10 | N6: 95000 | O6: 12 | P6: 11400 | Q6: 91 | R6: Excellent | S6: Active | T6: B.Tech | U6: Python;SQL;Cloud;Git;Spark | V6: 8 | W6: 9
A7: 1006 | B7: Sneha | C7: Iyer | D7: Sneha Iyer | E7: sneha.iyer@example.com | F7: Finance | G7: Finance Manager | H7: Chennai | I7: Tamil Nadu | J7: Office | K7: Full-Time | L7: 2017 | M7: 9 | N7: 85000 | O7: 12 | P7: 10200 | Q7: 89 | R7: Good | S7: Active | T7: M.Com | U7: Excel;Accounting;Power BI;Financial Analysis | V7: 6 | W7: 11
A8: 1007 | B8: Kiran | C8: Reddy | D8: Kiran Reddy | E8: kiran.reddy@example.com | F8: Sales | G8: Sales Executive | H8: Hyderabad | I8: Telangana | J8: Office | K8: Full-Time | L8: 2024 | M8: 2 | N8: 45000 | O8: 5 | P8: 2250 | Q8: 72 | R8: Average | S8: Active | T8: MBA | U8: CRM;Negotiation;Excel;Communication | V8: 1 | W8: 18
A9: 1008 | B9: Anitha | C9: Joseph | D9: Anitha Joseph | F9: Sales | G9: Sales Manager | H9: Bengaluru | I9: Karnataka | J9: Hybrid | K9: Full-Time | L9: 2019 | M9: 7 | N9: 78000 | O9: 12 | P9: 9360 | Q9: 86 | R9: Good | S9: Active | T9: MBA | U9: CRM;Negotiation;Excel;Communication | V9: 5 | W9: 7
A10: 1009 | B10: Vijay | C10: Kumar | D10: Vijay Kumar | E10: vijay.kumar@example.com | F10: IT | G10: DevOps Engineer | H10: Chennai | I10: Tamil Nadu | J10: Remote | K10: Full-Time | L10: 2018 | M10: 8 | N10: 88000 | O10: 15 | P10: 13200 | Q10: 94 | R10: Excellent | S10: Active | T10: B.Tech | U10: Python;SQL;Cloud;Git;Spark | V10: 7 | W10: 6
A11: 1010 | B11: Divya | C11: Nair | D11: Divya Nair | E11: divya.nair@example.com | F11: HR | G11: Recruiter | H11: Kochi | I11: Kerala | J11: Hybrid | K11: Full-Time | L11: 2021 | M11: 5 | N11: 52000 | O11: 8 | P11: 4160 | Q11: 83 | R11: Good | S11: Active | T11: MBA | U11: Recruitment;Excel;HRIS;Communication | V11: 4 | W11: 14
A12: 1011 | B12: John | C12: Mathew | D12: John Mathew | E12: john.mathew@example.com | F12: IT | G12: Software Engineer | H12: Pune | I12: Maharashtra | J12: Hybrid | K12: Full-Time | L12: 2022 | M12: 4 | N12: 60000 | O12: 8 | P12: 4800 | Q12: 81 | R12: Good | S12: Active | T12: B.Tech | U12: Python;SQL;Cloud;Git;Spark | V12: 3 | W12: 13
A13: 1012 | B13: Lakshmi | C13: Devi | D13: Lakshmi Devi | E13: lakshmi.devi@example.com | F13: Finance | G13: Senior Accountant | H13: Chennai | I13: Tamil Nadu | J13: Office | K13: Full-Time | L13: 2019 | M13: 7 | N13: 72000 | O13: 12 | P13: 8640 | Q13: 90 | R13: Excellent | S13: Active | T13: M.Com | U13: Excel;Accounting;Power BI;Financial Analysis | V13: 6 | W13: 9
A14: 1013 | B14: Suresh | C14: Babu | D14: Suresh Babu | E14: suresh.babu@example.com | F14: Operations | G14: Operations Manager | H14: Hyderabad | I14: Telangana | J14: Office | K14: Full-Time | L14: 2016 | M14: 10 | N14: 82000 | O14: 12 | P14: 9840 | Q14: 87 | R14: Good | S14: Active | T14: MBA | U14: Excel;SQL;Power BI;Process Management | V14: 7 | W14: 8
A15: 1014 | B15: Nandhini | C15: Raj | D15: Nandhini Raj | E15: nandhini.raj@example.com | F15: Marketing | G15: Marketing Executive | H15: Chennai | I15: Tamil Nadu | J15: Hybrid | K15: Full-Time | L15: 2022 | M15: 4 | N15: 55000 | O15: 8 | P15: 4400 | Q15: 79 | R15: Average | S15: Active | T15: MBA | U15: SEO;Google Analytics;Content;Social Media | V15: 3 | W15: 16
A16: 1015 | B16: Ravi | C16: Prakash | D16: Ravi Prakash | E16: ravi.prakash@example.com | F16: IT | G16: Python Developer | H16: Pune | I16: Maharashtra | J16: Remote | K16: Full-Time | L16: 2020 | M16: 6 | N16: 70000 | O16: 15 | P16: 10500 | Q16: 93 | R16: Excellent | S16: Active | T16: B.Tech | U16: Python;SQL;Cloud;Git;Spark | V16: 5 | W16: 10
A17: 1016 | B17: Asha | C17: Menon | D17: Asha Menon | E17: asha.menon@example.com | F17: HR | G17: HR Executive | H17: Kochi | I17: Kerala | J17: Office | K17: Full-Time | L17: 2023 | M17: 3 | N17: 48000 | O17: 8 | P17: 3840 | Q17: 76 | R17: Average | S17: Active | T17: MBA | U17: Recruitment;Excel;HRIS;Communication | V17: 2 | W17: 19
A18: 1017 | B18: Manoj | C18: Singh | D18: Manoj Singh | E18: manoj.singh@example.com | F18: Sales | G18: Business Development Executive | H18: Delhi | I18: Delhi | J18: Hybrid | K18: Full-Time | L18: 2021 | M18: 5 | N18: 58000 | O18: 8 | P18: 4640 | Q18: 84 | R18: Good | S18: Active | T18: MBA | V18: 4 | W18: 12
A19: 1018 | B19: Deepa | C19: Krishnan | D19: Deepa Krishnan | E19: deepa.krishnan@example.com | F19: IT | G19: BI Developer | H19: Bengaluru | I19: Karnataka | J19: Hybrid | K19: Full-Time | L19: 2019 | M19: 7 | N19: 76000 | O19: 12 | P19: 9120 | Q19: 89 | R19: Good | S19: Active | T19: B.Tech | U19: Python;SQL;Cloud;Git;Spark | V19: 6 | W19: 11
A20: 1019 | B20: Gokul | C20: Raj | D20: Gokul Raj | E20: gokul.raj@example.com | F20: Operations | G20: Operations Executive | H20: Coimbatore | I20: Tamil Nadu | J20: Office | K20: Full-Time | L20: 2023 | M20: 3 | N20: 47000 | O20: 5 | P20: 2350 | Q20: 73 | R20: Average | S20: Active | T20: MBA | U20: Excel;SQL;Power BI;Process Management | V20: 2 | W20: 17
A21: 1020 | B21: Swathi | C21: Rao | D21: Swathi Rao | E21: swathi.rao@example.com | F21: Marketing | G21: Digital Marketing Specialist | H21: Hyderabad | I21: Telangana | J21: Remote | K21: Full-Time | L21: 2020 | M21: 6 | N21: 68000 | O21: 12 | P21: 8160 | Q21: 91 | R21: Excellent | S21: Active | T21: MBA | U21: SEO;Google Analytics;Content;Social Media | V21: 5 | W21: 7
A22: 1021 | B22: Karthik | C22: Mohan | D22: Karthik Mohan | E22: karthik.mohan@example.com | F22: IT | G22: Azure Data Engineer | H22: Chennai | I22: Tamil Nadu | J22: Hybrid | K22: Full-Time | L22: 2018 | M22: 8 | N22: 92000 | O22: 15 | P22: 13800 | Q22: 96 | R22: Excellent | S22: Active | T22: B.Tech | U22: Python;SQL;Cloud;Git;Spark | V22: 8 | W22: 8
A23: 1022 | B23: Neha | C23: Gupta | D23: Neha Gupta | E23: neha.gupta@example.com | F23: Finance | G23: Finance Executive | H23: Delhi | I23: Delhi | J23: Office | K23: Full-Time | L23: 2021 | M23: 5 | N23: 57000 | O23: 8 | P23: 4560 | Q23: 82 | R23: Good | S23: Active | T23: M.Com | U23: Excel;Accounting;Power BI;Financial Analysis | V23: 3 | W23: 13
A24: 1023 | B24: Vishnu | C24: Menon | D24: Vishnu Menon | E24: vishnu.menon@example.com | F24: IT | G24: Database Administrator | H24: Kochi | I24: Kerala | J24: Hybrid | K24: Full-Time | L24: 2017 | M24: 9 | N24: 84000 | O24: 12 | P24: 10080 | Q24: 88 | R24: Good | S24: Active | T24: B.Tech | U24: Python;SQL;Cloud;Git;Spark | V24: 6 | W24: 9
A25: 1024 | B25: Pooja | C25: Patel | D25: Pooja Patel | E25: pooja.patel@example.com | F25: Sales | G25: Sales Executive | H25: Ahmedabad | I25: Gujarat | J25: Office | K25: Full-Time | L25: 2023 | M25: 3 | N25: 46000 | O25: 5 | P25: 2300 | Q25: 71 | R25: Average | S25: Active | T25: MBA | U25: CRM;Negotiation;Excel;Communication | V25: 2 | W25: 16
A26: 1025 | B26: Harish | C26: Kumar | D26: Harish Kumar | E26: harish.kumar@example.com | F26: Operations | G26: Business Analyst | H26: Pune | I26: Maharashtra | J26: Hybrid | K26: Full-Time | L26: 2020 | M26: 6 | N26: 67000 | O26: 12 | P26: 8040 | Q26: 85 | R26: Good | S26: Active | U26: Excel;SQL;Power BI;Process Management | V26: 5 | W26: 10
A27: 1026 | B27: Keerthi | C27: Ramesh | D27: Keerthi Ramesh | E27: keerthi.ramesh@example.com | F27: IT | G27: Machine Learning Engineer | H27: Bengaluru | I27: Karnataka | J27: Remote | K27: Full-Time | L27: 2019 | M27: 7 | N27: 98000 | O27: 15 | P27: 14700 | Q27: 97 | R27: Excellent | S27: Active | T27: B.Tech | U27: Python;SQL;Cloud;Git;Spark | V27: 8 | W27: 6
A28: 1027 | B28: Sanjay | C28: Das | D28: Sanjay Das | E28: sanjay.das@example.com | F28: Finance | G28: Senior Financial Analyst | H28: Kolkata | I28: West Bengal | J28: Hybrid | K28: Full-Time | L28: 2018 | M28: 8 | N28: 79000 | O28: 12 | P28: 9480 | Q28: 86 | R28: Good | S28: Active | T28: M.Com | U28: Excel;Accounting;Power BI;Financial Analysis | V28: 4 | W28: 12
A29: 1028 | B29: Maya | C29: Thomas | D29: Maya Thomas | E29: maya.thomas@example.com | F29: HR | G29: Talent Acquisition Specialist | H29: Kochi | I29: Kerala | J29: Hybrid | K29: Full-Time | L29: 2020 | M29: 6 | N29: 61000 | O29: 12 | P29: 7320 | Q29: 90 | R29: Excellent | S29: Active | T29: MBA | U29: Recruitment;Excel;HRIS;Communication | V29: 5 | W29: 8
A30: 1029 | B30: Ajay | C30: Rajan | D30: Ajay Rajan | E30: ajay.rajan@example.com | F30: IT | G30: Full Stack Developer | H30: Chennai | I30: Tamil Nadu | J30: Office | K30: Full-Time | L30: 2021 | M30: 5 | N30: 73000 | O30: 8 | P30: 5840 | Q30: 80 | R30: Good | S30: Active | T30: B.Tech | U30: Python;SQL;Cloud;Git;Spark | V30: 4 | W30: 14
A31: 1030 | B31: Roshini | C31: Paul | D31: Roshini Paul | E31: roshini.paul@example.com | F31: Marketing | G31: Content Strategist | H31: Kochi | I31: Kerala | J31: Remote | K31: Full-Time | L31: 2022 | M31: 4 | N31: 59000 | O31: 12 | P31: 7080 | Q31: 87 | R31: Good | S31: Active | T31: MBA | U31: SEO;Google Analytics;Content;Social Media | V31: 3 | W31: 11
A32: 1031 | B32: Bharath | C32: Rao | D32: Bharath Rao | E32: bharath.rao@example.com | F32: IT | G32: Cloud Architect | H32: Hyderabad | I32: Telangana | J32: Hybrid | K32: Full-Time | L32: 2016 | M32: 10 | N32: 125000 | O32: 15 | P32: 18750 | Q32: 95 | R32: Excellent | S32: Active | T32: B.Tech | U32: Python;SQL;Cloud;Git;Spark | V32: 9 | W32: 7
A33: 1032 | B33: Ishita | C33: Roy | D33: Ishita Roy | E33: ishita.roy@example.com | F33: Finance | G33: Financial Analyst | H33: Kolkata | I33: West Bengal | J33: Office | K33: Full-Time | L33: 2022 | M33: 4 | N33: 60000 | O33: 8 | P33: 4800 | Q33: 78 | R33: Average | S33: Active | T33: M.Com | U33: Excel;Accounting;Power BI;Financial Analysis | V33: 3 | W33: 15
A34: 1033 | B34: Naveen | C34: Kumar | D34: Naveen Kumar | E34: naveen.kumar@example.com | F34: Sales | G34: Regional Sales Manager | H34: Pune | I34: Maharashtra | J34: Hybrid | K34: Full-Time | L34: 2017 | M34: 9 | N34: 98000 | O34: 15 | P34: 14700 | Q34: 93 | R34: Excellent | S34: Active | T34: MBA | U34: CRM;Negotiation;Excel;Communication | V34: 7 | W34: 9
A35: 1034 | B35: Harini | C35: S | D35: Harini S | E35: harini.s@example.com | F35: IT | G35: QA Engineer | H35: Chennai | I35: Tamil Nadu | J35: Office | K35: Full-Time | L35: 2023 | M35: 3 | N35: 52000 | O35: 8 | P35: 4160 | Q35: 75 | R35: Average | S35: Active | T35: B.Tech | U35: Python;SQL;Cloud;Git;Spark | V35: 2 | W35: 18
A36: 1035 | B36: Mohan | C36: Raj | D36: Mohan Raj | E36: mohan.raj@example.com | F36: Operations | G36: Supply Chain Analyst | H36: Coimbatore | I36: Tamil Nadu | J36: Hybrid | K36: Full-Time | L36: 2021 | M36: 5 | N36: 62000 | O36: 8 | P36: 4960 | Q36: 83 | R36: Good | S36: Active | T36: MBA | U36: Excel;SQL;Power BI;Process Management | V36: 4
A37: 1036 | B37: Aparna | C37: Krish | D37: Aparna Krish | E37: aparna.krish@example.com | F37: HR | G37: Learning Specialist | H37: Bengaluru | I37: Karnataka | J37: Remote | K37: Full-Time | L37: 2022 | M37: 4 | N37: 56000 | O37: 12 | P37: 6720 | Q37: 88 | R37: Good | S37: Active | T37: MBA | U37: Recruitment;Excel;HRIS;Communication | V37: 3 | W37: 10
A38: 1037 | B38: Dinesh | C38: Yadav | D38: Dinesh Yadav | E38: dinesh.yadav@example.com | F38: IT | G38: Network Engineer | H38: Delhi | I38: Delhi | J38: Office | K38: Full-Time | L38: 2019 | M38: 7 | N38: 72000 | O38: 8 | P38: 5760 | Q38: 84 | R38: Good | S38: Active | T38: B.Tech | U38: Python;SQL;Cloud;Git;Spark | V38: 5 | W38: 12
A39: 1038 | B39: Sangeetha | C39: M | D39: Sangeetha M | E39: sangeetha.m@example.com | F39: Marketing | G39: Marketing Manager | H39: Bengaluru | I39: Karnataka | J39: Hybrid | K39: Full-Time | L39: 2018 | M39: 8 | N39: 88000 | O39: 15 | P39: 13200 | Q39: 92 | R39: Excellent | S39: Active | T39: MBA | U39: SEO;Google Analytics;Content;Social Media | V39: 6 | W39: 8
A40: 1039 | B40: Prakash | C40: N | D40: Prakash N | E40: prakash.n@example.com | F40: IT | G40: Data Analyst | H40: Chennai | I40: Tamil Nadu | J40: Hybrid | K40: Full-Time | L40: 2023 | M40: 3 | N40: 56000 | O40: 12 | P40: 6720 | Q40: 86 | R40: Good | S40: Active | T40: B.Tech | U40: Python;SQL;Cloud;Git;Spark | V40: 3 | W40: 15
...

Sheet Clean_Data
A1: Employee_ID | B1: First_Name | C1: Last_Name | D1: Full_Name | E1: Email | F1: Department | G1: Job_Title | H1: City | I1: State | J1: Work_Mode | K1: Employment_Type | L1: Joining_Year | M1: Experience_Years | N1: Annual_Salary | O1: Bonus_Percentage | P1: Bonus_Amount | Q1: Performance_Score | R1: Performance_Rating | S1: Status | T1: Education | U1: Skills | V1: Projects_Count | W1: Leave_Balance_Days | X1: Email_Check | Y1: Skills_Check | Z1: Education_Check | AA1: Leave_Check | AB1: Calculated_Full_Name | AC1: Calculated_Bonus | AD1: Salary_Band | AE1: Experience_Band | AF1: Performance_Check
A2: 1001 | B2: Arun | C2: Kumar | D2: Arun Kumar | E2: arun.kumar@example.com | F2: IT | G2: Data Engineer | H2: Chennai | I2: Tamil Nadu | J2: Hybrid | K2: Full-Time | L2: 2019 | M2: 7 | N2: 65000 | O2: 12 | P2: 7800 | Q2: 88 | R2: Good | S2: Active | T2: B.Tech | U2: Python;SQL;Cloud;Git;Spark | V2: 2 | W2: 12 | X2: =IF(E2="","Missing Email","Available") -> Available | Y2: =IF(U2="","Missing Skills","Available") -> Available | Z2: =IF(T2="","Missing Education","Available") -> Available | AA2: =IF(W2="","Missing Leave Balance","Available") -> Available | AB2: =TRIM(B2&" "&C2) -> Arun Kumar | AC2: =ROUND(N2*O2/100,0) -> 7800 | AD2: =IF(N2>=90000,"High",IF(N2>=60000,"Medium","Low")) -> Medium | AE2: =IF(M2>=8,"Senior",IF(M2>=5,"Mid-Level","Junior")) -> Mid-Level | AF2: =IF(Q2>=90,"Top Performer",IF(Q2>=75,"Meets Expectations","Needs Improvement")) -> Meets Expectations
A3: 1002 | B3: Priya | C3: Sharma | D3: Priya Sharma | E3: priya.sharma@example.com | F3: HR | G3: HR Manager | H3: Bengaluru | I3: Karnataka | J3: Hybrid | K3: Full-Time | L3: 2018 | M3: 8 | N3: 75000 | O3: 15 | P3: 11250 | Q3: 92 | R3: Excellent | S3: Active | T3: MBA | U3: Recruitment;Excel;HRIS;Communication | V3: 5 | W3: 8 | X3: =IF(E3="","Missing Email","Available") -> Available | Y3: =IF(U3="","Missing Skills","Available") -> Available | Z3: =IF(T3="","Missing Education","Available") -> Available | AA3: =IF(W3="","Missing Leave Balance","Available") -> Available | AB3: =TRIM(B3&" "&C3) -> Priya Sharma | AC3: =ROUND(N3*O3/100,0) -> 11250 | AD3: =IF(N3>=90000,"High",IF(N3>=60000,"Medium","Low")) -> Medium | AE3: =IF(M3>=8,"Senior",IF(M3>=5,"Mid-Level","Junior")) -> Senior | AF3: =IF(Q3>=90,"Top Performer",IF(Q3>=75,"Meets Expectations","Needs Improvement")) -> Top Performer
A4: 1003 | B4: David | C4: Wilson | D4: David Wilson | E4: david.wilson@example.com | F4: IT | G4: Senior Data Engineer | H4: Chennai | I4: Tamil Nadu | J4: Remote | K4: Full-Time | L4: 2017 | M4: 9 | N4: 90000 | O4: 15 | P4: 13500 | Q4: 95 | R4: Excellent | S4: Active | T4: B.Tech | U4: Python;SQL;Cloud;Git;Spark | V4: 7 | W4: 10 | X4: =IF(E4="","Missing Email","Available") -> Available | Y4: =IF(U4="","Missing Skills","Available") -> Available | Z4: =IF(T4="","Missing Education","Available") -> Available | AA4: =IF(W4="","Missing Leave Balance","Available") -> Available | AB4: =TRIM(B4&" "&C4) -> David Wilson | AC4: =ROUND(N4*O4/100,0) -> 13500 | AD4: =IF(N4>=90000,"High",IF(N4>=60000,"Medium","Low")) -> High | AE4: =IF(M4>=8,"Senior",IF(M4>=5,"Mid-Level","Junior")) -> Senior | AF4: =IF(Q4>=90,"Top Performer",IF(Q4>=75,"Meets Expectations","Needs Improvement")) -> Top Performer
A5: 1004 | B5: Meena | C5: Ravi | D5: Meena Ravi | E5: meena.ravi@example.com | F5: Finance | G5: Financial Analyst | H5: Hyderabad | I5: Telangana | J5: Office | K5: Full-Time | L5: 2020 | M5: 6 | N5: 65000 | O5: 8 | P5: 5200 | Q5: 78 | R5: Average | S5: Active | T5: M.Com | U5: Excel;Accounting;Power BI;Financial Analysis | V5: 3 | W5: 15 | X5: =IF(E5="","Missing Email","Available") -> Available | Y5: =IF(U5="","Missing Skills","Available") -> Available | Z5: =IF(T5="","Missing Education","Available") -> Available | AA5: =IF(W5="","Missing Leave Balance","Available") -> Available | AB5: =TRIM(B5&" "&C5) -> Meena Ravi | AC5: =ROUND(N5*O5/100,0) -> 5200 | AD5: =IF(N5>=90000,"High",IF(N5>=60000,"Medium","Low")) -> Medium | AE5: =IF(M5>=8,"Senior",IF(M5>=5,"Mid-Level","Junior")) -> Mid-Level | AF5: =IF(Q5>=90,"Top Performer",IF(Q5>=75,"Meets Expectations","Needs Improvement")) -> Meets Expectations
A6: 1005 | B6: Rahul | C6: Verma | D6: Rahul Verma | E6: rahul.verma@example.com | F6: IT | G6: Cloud Engineer | H6: Bengaluru | I6: Karnataka | J6: Hybrid | K6: Full-Time | L6: 2016 | M6: 10 | N6: 95000 | O6: 12 | P6: 11400 | Q6: 91 | R6: Excellent | S6: Active | T6: B.Tech | U6: Python;SQL;Cloud;Git;Spark | V6: 8 | W6: 9 | X6: =IF(E6="","Missing Email","Available") -> Available | Y6: =IF(U6="","Missing Skills","Available") -> Available | Z6: =IF(T6="","Missing Education","Available") -> Available | AA6: =IF(W6="","Missing Leave Balance","Available") -> Available | AB6: =TRIM(B6&" "&C6) -> Rahul Verma | AC6: =ROUND(N6*O6/100,0) -> 11400 | AD6: =IF(N6>=90000,"High",IF(N6>=60000,"Medium","Low")) -> High | AE6: =IF(M6>=8,"Senior",IF(M6>=5,"Mid-Level","Junior")) -> Senior | AF6: =IF(Q6>=90,"Top Performer",IF(Q6>=75,"Meets Expectations","Needs Improvement")) -> Top Performer
A7: 1006 | B7: Sneha | C7: Iyer | D7: Sneha Iyer | E7: sneha.iyer@example.com | F7: Finance | G7: Finance Manager | H7: Chennai | I7: Tamil Nadu | J7: Office | K7: Full-Time | L7: 2017 | M7: 9 | N7: 85000 | O7: 12 | P7: 10200 | Q7: 89 | R7: Good | S7: Active | T7: M.Com | U7: Excel;Accounting;Power BI;Financial Analysis | V7: 6 | W7: 11 | X7: =IF(E7="","Missing Email","Available") -> Available | Y7: =IF(U7="","Missing Skills","Available") -> Available | Z7: =IF(T7="","Missing Education","Available") -> Available | AA7: =IF(W7="","Missing Leave Balance","Available") -> Available | AB7: =TRIM(B7&" "&C7) -> Sneha Iyer | AC7: =ROUND(N7*O7/100,0) -> 10200 | AD7: =IF(N7>=90000,"High",IF(N7>=60000,"Medium","Low")) -> Medium | AE7: =IF(M7>=8,"Senior",IF(M7>=5,"Mid-Level","Junior")) -> Senior | AF7: =IF(Q7>=90,"Top Performer",IF(Q7>=75,"Meets Expectations","Needs Improvement")) -> Meets Expectations
A8: 1007 | B8: Kiran | C8: Reddy | D8: Kiran Reddy | E8: kiran.reddy@example.com | F8: Sales | G8: Sales Executive | H8: Hyderabad | I8: Telangana | J8: Office | K8: Full-Time | L8: 2024 | M8: 2 | N8: 45000 | O8: 5 | P8: 2250 | Q8: 72 | R8: Average | S8: Active | T8: MBA | U8: CRM;Negotiation;Excel;Communication | V8: 1 | W8: 18 | X8: =IF(E8="","Missing Email","Available") -> Available | Y8: =IF(U8="","Missing Skills","Available") -> Available | Z8: =IF(T8="","Missing Education","Available") -> Available | AA8: =IF(W8="","Missing Leave Balance","Available") -> Available | AB8: =TRIM(B8&" "&C8) -> Kiran Reddy | AC8: =ROUND(N8*O8/100,0) -> 2250 | AD8: =IF(N8>=90000,"High",IF(N8>=60000,"Medium","Low")) -> Low | AE8: =IF(M8>=8,"Senior",IF(M8>=5,"Mid-Level","Junior")) -> Junior | AF8: =IF(Q8>=90,"Top Performer",IF(Q8>=75,"Meets Expectations","Needs Improvement")) -> Needs Improvement
A9: 1008 | B9: Anitha | C9: Joseph | D9: Anitha Joseph | F9: Sales | G9: Sales Manager | H9: Bengaluru | I9: Karnataka | J9: Hybrid | K9: Full-Time | L9: 2019 | M9: 7 | N9: 78000 | O9: 12 | P9: 9360 | Q9: 86 | R9: Good | S9: Active | T9: MBA | U9: CRM;Negotiation;Excel;Communication | V9: 5 | W9: 7 | X9: =IF(E9="","Missing Email","Available") -> Missing Email | Y9: =IF(U9="","Missing Skills","Available") -> Available | Z9: =IF(T9="","Missing Education","Available") -> Available | AA9: =IF(W9="","Missing Leave Balance","Available") -> Available | AB9: =TRIM(B9&" "&C9) -> Anitha Joseph | AC9: =ROUND(N9*O9/100,0) -> 9360 | AD9: =IF(N9>=90000,"High",IF(N9>=60000,"Medium","Low")) -> Medium | AE9: =IF(M9>=8,"Senior",IF(M9>=5,"Mid-Level","Junior")) -> Mid-Level | AF9: =IF(Q9>=90,"Top Performer",IF(Q9>=75,"Meets Expectations","Needs Improvement")) -> Meets Expectations
A10: 1009 | B10: Vijay | C10: Kumar | D10: Vijay Kumar | E10: vijay.kumar@example.com | F10: IT | G10: DevOps Engineer | H10: Chennai | I10: Tamil Nadu | J10: Remote | K10: Full-Time | L10: 2018 | M10: 8 | N10: 88000 | O10: 15 | P10: 13200 | Q10: 94 | R10: Excellent | S10: Active | T10: B.Tech | U10: Python;SQL;Cloud;Git;Spark | V10: 7 | W10: 6 | X10: =IF(E10="","Missing Email","Available") -> Available | Y10: =IF(U10="","Missing Skills","Available") -> Available | Z10: =IF(T10="","Missing Education","Available") -> Available | AA10: =IF(W10="","Missing Leave Balance","Available") -> Available | AB10: =TRIM(B10&" "&C10) -> Vijay Kumar | AC10: =ROUND(N10*O10/100,0) -> 13200 | AD10: =IF(N10>=90000,"High",IF(N10>=60000,"Medium","Low")) -> Medium | AE10: =IF(M10>=8,"Senior",IF(M10>=5,"Mid-Level","Junior")) -> Senior | AF10: =IF(Q10>=90,"Top Performer",IF(Q10>=75,"Meets Expectations","Needs Improvement")) -> Top Performer
A11: 1010 | B11: Divya | C11: Nair | D11: Divya Nair | E11: divya.nair@example.com | F11: HR | G11: Recruiter | H11: Kochi | I11: Kerala | J11: Hybrid | K11: Full-Time | L11: 2021 | M11: 5 | N11: 52000 | O11: 8 | P11: 4160 | Q11: 83 | R11: Good | S11: Active | T11: MBA | U11: Recruitment;Excel;HRIS;Communication | V11: 4 | W11: 14 | X11: =IF(E11="","Missing Email","Available") -> Available | Y11: =IF(U11="","Missing Skills","Available") -> Available | Z11: =IF(T11="","Missing Education","Available") -> Available | AA11: =IF(W11="","Missing Leave Balance","Available") -> Available | AB11: =TRIM(B11&" "&C11) -> Divya Nair | AC11: =ROUND(N11*O11/100,0) -> 4160 | AD11: =IF(N11>=90000,"High",IF(N11>=60000,"Medium","Low")) -> Low | AE11: =IF(M11>=8,"Senior",IF(M11>=5,"Mid-Level","Junior")) -> Mid-Level | AF11: =IF(Q11>=90,"Top Performer",IF(Q11>=75,"Meets Expectations","Needs Improvement")) -> Meets Expectations
A12: 1011 | B12: John | C12: Mathew | D12: John Mathew | E12: john.mathew@example.com | F12: IT | G12: Software Engineer | H12: Pune | I12: Maharashtra | J12: Hybrid | K12: Full-Time | L12: 2022 | M12: 4 | N12: 60000 | O12: 8 | P12: 4800 | Q12: 81 | R12: Good | S12: Active | T12: B.Tech | U12: Python;SQL;Cloud;Git;Spark | V12: 3 | W12: 13 | X12: =IF(E12="","Missing Email","Available") -> Available | Y12: =IF(U12="","Missing Skills","Available") -> Available | Z12: =IF(T12="","Missing Education","Available") -> Available | AA12: =IF(W12="","Missing Leave Balance","Available") -> Available | AB12: =TRIM(B12&" "&C12) -> John Mathew | AC12: =ROUND(N12*O12/100,0) -> 4800 | AD12: =IF(N12>=90000,"High",IF(N12>=60000,"Medium","Low")) -> Medium | AE12: =IF(M12>=8,"Senior",IF(M12>=5,"Mid-Level","Junior")) -> Junior | AF12: =IF(Q12>=90,"Top Performer",IF(Q12>=75,"Meets Expectations","Needs Improvement")) -> Meets Expectations
A13: 1012 | B13: Lakshmi | C13: Devi | D13: Lakshmi Devi | E13: lakshmi.devi@example.com | F13: Finance | G13: Senior Accountant | H13: Chennai | I13: Tamil Nadu | J13: Office | K13: Full-Time | L13: 2019 | M13: 7 | N13: 72000 | O13: 12 | P13: 8640 | Q13: 90 | R13: Excellent | S13: Active | T13: M.Com | U13: Excel;Accounting;Power BI;Financial Analysis | V13: 6 | W13: 9 | X13: =IF(E13="","Missing Email","Available") -> Available | Y13: =IF(U13="","Missing Skills","Available") -> Available | Z13: =IF(T13="","Missing Education","Available") -> Available | AA13: =IF(W13="","Missing Leave Balance","Available") -> Available | AB13: =TRIM(B13&" "&C13) -> Lakshmi Devi | AC13: =ROUND(N13*O13/100,0) -> 8640 | AD13: =IF(N13>=90000,"High",IF(N13>=60000,"Medium","Low")) -> Medium | AE13: =IF(M13>=8,"Senior",IF(M13>=5,"Mid-Level","Junior")) -> Mid-Level | AF13: =IF(Q13>=90,"Top Performer",IF(Q13>=75,"Meets Expectations","Needs Improvement")) -> Top Performer
A14: 1013 | B14: Suresh | C14: Babu | D14: Suresh Babu | E14: suresh.babu@example.com | F14: Operations | G14: Operations Manager | H14: Hyderabad | I14: Telangana | J14: Office | K14: Full-Time | L14: 2016 | M14: 10 | N14: 82000 | O14: 12 | P14: 9840 | Q14: 87 | R14: Good | S14: Active | T14: MBA | U14: Excel;SQL;Power BI;Process Management | V14: 7 | W14: 8 | X14: =IF(E14="","Missing Email","Available") -> Available | Y14: =IF(U14="","Missing Skills","Available") -> Available | Z14: =IF(T14="","Missing Education","Available") -> Available | AA14: =IF(W14="","Missing Leave Balance","Available") -> Available | AB14: =TRIM(B14&" "&C14) -> Suresh Babu | AC14: =ROUND(N14*O14/100,0) -> 9840 | AD14: =IF(N14>=90000,"High",IF(N14>=60000,"Medium","Low")) -> Medium | AE14: =IF(M14>=8,"Senior",IF(M14>=5,"Mid-Level","Junior")) -> Senior | AF14: =IF(Q14>=90,"Top Performer",IF(Q14>=75,"Meets Expectations","Needs Improvement")) -> Meets Expectations
A15: 1014 | B15: Nandhini | C15: Raj | D15: Nandhini Raj | E15: nandhini.raj@example.com | F15: Marketing | G15: Marketing Executive | H15: Chennai | I15: Tamil Nadu | J15: Hybrid | K15: Full-Time | L15: 2022 | M15: 4 | N15: 55000 | O15: 8 | P15: 4400 | Q15: 79 | R15: Average | S15: Active | T15: MBA | U15: SEO;Google Analytics;Content;Social Media | V15: 3 | W15: 16 | X15: =IF(E15="","Missing Email","Available") -> Available | Y15: =IF(U15="","Missing Skills","Available") -> Available | Z15: =IF(T15="","Missing Education","Available") -> Available | AA15: =IF(W15="","Missing Leave Balance","Available") -> Available | AB15: =TRIM(B15&" "&C15) -> Nandhini Raj | AC15: =ROUND(N15*O15/100,0) -> 4400 | AD15: =IF(N15>=90000,"High",IF(N15>=60000,"Medium","Low")) -> Low | AE15: =IF(M15>=8,"Senior",IF(M15>=5,"Mid-Level","Junior")) -> Junior | AF15: =IF(Q15>=90,"Top Performer",IF(Q15>=75,"Meets Expectations","Needs Improvement")) -> Meets Expectations
A16: 1015 | B16: Ravi | C16: Prakash | D16: Ravi Prakash | E16: ravi.prakash@example.com | F16: IT | G16: Python Developer | H16: Pune | I16: Maharashtra | J16: Remote | K16: Full-Time | L16: 2020 | M16: 6 | N16: 70000 | O16: 15 | P16: 10500 | Q16: 93 | R16: Excellent | S16: Active | T16: B.Tech | U16: Python;SQL;Cloud;Git;Spark | V16: 5 | W16: 10 | X16: =IF(E16="","Missing Email","Available") -> Available | Y16: =IF(U16="","Missing Skills","Available") -> Available | Z16: =IF(T16="","Missing Education","Available") -> Available | AA16: =IF(W16="","Missing Leave Balance","Available") -> Available | AB16: =TRIM(B16&" "&C16) -> Ravi Prakash | AC16: =ROUND(N16*O16/100,0) -> 10500 | AD16: =IF(N16>=90000,"High",IF(N16>=60000,"Medium","Low")) -> Medium | AE16: =IF(M16>=8,"Senior",IF(M16>=5,"Mid-Level","Junior")) -> Mid-Level | AF16: =IF(Q16>=90,"Top Performer",IF(Q16>=75,"Meets Expectations","Needs Improvement")) -> Top Performer
A17: 1016 | B17: Asha | C17: Menon | D17: Asha Menon | E17: asha.menon@example.com | F17: HR | G17: HR Executive | H17: Kochi | I17: Kerala | J17: Office | K17: Full-Time | L17: 2023 | M17: 3 | N17: 48000 | O17: 8 | P17: 3840 | Q17: 76 | R17: Average | S17: Active | T17: MBA | U17: Recruitment;Excel;HRIS;Communication | V17: 2 | W17: 19 | X17: =IF(E17="","Missing Email","Available") -> Available | Y17: =IF(U17="","Missing Skills","Available") -> Available | Z17: =IF(T17="","Missing Education","Available") -> Available | AA17: =IF(W17="","Missing Leave Balance","Available") -> Available | AB17: =TRIM(B17&" "&C17) -> Asha Menon | AC17: =ROUND(N17*O17/100,0) -> 3840 | AD17: =IF(N17>=90000,"High",IF(N17>=60000,"Medium","Low")) -> Low | AE17: =IF(M17>=8,"Senior",IF(M17>=5,"Mid-Level","Junior")) -> Junior | AF17: =IF(Q17>=90,"Top Performer",IF(Q17>=75,"Meets Expectations","Needs Improvement")) -> Meets Expectations
A18: 1017 | B18: Manoj | C18: Singh | D18: Manoj Singh | E18: manoj.singh@example.com | F18: Sales | G18: Business Development Executive | H18: Delhi | I18: Delhi | J18: Hybrid | K18: Full-Time | L18: 2021 | M18: 5 | N18: 58000 | O18: 8 | P18: 4640 | Q18: 84 | R18: Good | S18: Active | T18: MBA | V18: 4 | W18: 12 | X18: =IF(E18="","Missing Email","Available") -> Available | Y18: =IF(U18="","Missing Skills","Available") -> Missing Skills | Z18: =IF(T18="","Missing Education","Available") -> Available | AA18: =IF(W18="","Missing Leave Balance","Available") -> Available | AB18: =TRIM(B18&" "&C18) -> Manoj Singh | AC18: =ROUND(N18*O18/100,0) -> 4640 | AD18: =IF(N18>=90000,"High",IF(N18>=60000,"Medium","Low")) -> Low | AE18: =IF(M18>=8,"Senior",IF(M18>=5,"Mid-Level","Junior")) -> Mid-Level | AF18: =IF(Q18>=90,"Top Performer",IF(Q18>=75,"Meets Expectations","Needs Improvement")) -> Meets Expectations
A19: 1018 | B19: Deepa | C19: Krishnan | D19: Deepa Krishnan | E19: deepa.krishnan@example.com | F19: IT | G19: BI Developer | H19: Bengaluru | I19: Karnataka | J19: Hybrid | K19: Full-Time | L19: 2019 | M19: 7 | N19: 76000 | O19: 12 | P19: 9120 | Q19: 89 | R19: Good | S19: Active | T19: B.Tech | U19: Python;SQL;Cloud;Git;Spark | V19: 6 | W19: 11 | X19: =IF(E19="","Missing Email","Available") -> Available | Y19: =IF(U19="","Missing Skills","Available") -> Available | Z19: =IF(T19="","Missing Education","Available") -> Available | AA19: =IF(W19="","Missing Leave Balance","Available") -> Available | AB19: =TRIM(B19&" "&C19) -> Deepa Krishnan | AC19: =ROUND(N19*O19/100,0) -> 9120 | AD19: =IF(N19>=90000,"High",IF(N19>=60000,"Medium","Low")) -> Medium | AE19: =IF(M19>=8,"Senior",IF(M19>=5,"Mid-Level","Junior")) -> Mid-Level | AF19: =IF(Q19>=90,"Top Performer",IF(Q19>=75,"Meets Expectations","Needs Improvement")) -> Meets Expectations
A20: 1019 | B20: Gokul | C20: Raj | D20: Gokul Raj | E20: gokul.raj@example.com | F20: Operations | G20: Operations Executive | H20: Coimbatore | I20: Tamil Nadu | J20: Office | K20: Full-Time | L20: 2023 | M20: 3 | N20: 47000 | O20: 5 | P20: 2350 | Q20: 73 | R20: Average | S20: Active | T20: MBA | U20: Excel;SQL;Power BI;Process Management | V20: 2 | W20: 17 | X20: =IF(E20="","Missing Email","Available") -> Available | Y20: =IF(U20="","Missing Skills","Available") -> Available | Z20: =IF(T20="","Missing Education","Available") -> Available | AA20: =IF(W20="","Missing Leave Balance","Available") -> Available | AB20: =TRIM(B20&" "&C20) -> Gokul Raj | AC20: =ROUND(N20*O20/100,0) -> 2350 | AD20: =IF(N20>=90000,"High",IF(N20>=60000,"Medium","Low")) -> Low | AE20: =IF(M20>=8,"Senior",IF(M20>=5,"Mid-Level","Junior")) -> Junior | AF20: =IF(Q20>=90,"Top Performer",IF(Q20>=75,"Meets Expectations","Needs Improvement")) -> Needs Improvement
A21: 1020 | B21: Swathi | C21: Rao | D21: Swathi Rao | E21: swathi.rao@example.com | F21: Marketing | G21: Digital Marketing Specialist | H21: Hyderabad | I21: Telangana | J21: Remote | K21: Full-Time | L21: 2020 | M21: 6 | N21: 68000 | O21: 12 | P21: 8160 | Q21: 91 | R21: Excellent | S21: Active | T21: MBA | U21: SEO;Google Analytics;Content;Social Media | V21: 5 | W21: 7 | X21: =IF(E21="","Missing Email","Available") -> Available | Y21: =IF(U21="","Missing Skills","Available") -> Available | Z21: =IF(T21="","Missing Education","Available") -> Available | AA21: =IF(W21="","Missing Leave Balance","Available") -> Available | AB21: =TRIM(B21&" "&C21) -> Swathi Rao | AC21: =ROUND(N21*O21/100,0) -> 8160 | AD21: =IF(N21>=90000,"High",IF(N21>=60000,"Medium","Low")) -> Medium | AE21: =IF(M21>=8,"Senior",IF(M21>=5,"Mid-Level","Junior")) -> Mid-Level | AF21: =IF(Q21>=90,"Top Performer",IF(Q21>=75,"Meets Expectations","Needs Improvement")) -> Top Performer
A22: 1021 | B22: Karthik | C22: Mohan | D22: Karthik Mohan | E22: karthik.mohan@example.com | F22: IT | G22: Azure Data Engineer | H22: Chennai | I22: Tamil Nadu | J22: Hybrid | K22: Full-Time | L22: 2018 | M22: 8 | N22: 92000 | O22: 15 | P22: 13800 | Q22: 96 | R22: Excellent | S22: Active | T22: B.Tech | U22: Python;SQL;Cloud;Git;Spark | V22: 8 | W22: 8 | X22: =IF(E22="","Missing Email","Available") -> Available | Y22: =IF(U22="","Missing Skills","Available") -> Available | Z22: =IF(T22="","Missing Education","Available") -> Available | AA22: =IF(W22="","Missing Leave Balance","Available") -> Available | AB22: =TRIM(B22&" "&C22) -> Karthik Mohan | AC22: =ROUND(N22*O22/100,0) -> 13800 | AD22: =IF(N22>=90000,"High",IF(N22>=60000,"Medium","Low")) -> High | AE22: =IF(M22>=8,"Senior",IF(M22>=5,"Mid-Level","Junior")) -> Senior | AF22: =IF(Q22>=90,"Top Performer",IF(Q22>=75,"Meets Expectations","Needs Improvement")) -> Top Performer
A23: 1022 | B23: Neha | C23: Gupta | D23: Neha Gupta | E23: neha.gupta@example.com | F23: Finance | G23: Finance Executive | H23: Delhi | I23: Delhi | J23: Office | K23: Full-Time | L23: 2021 | M23: 5 | N23: 57000 | O23: 8 | P23: 4560 | Q23: 82 | R23: Good | S23: Active | T23: M.Com | U23: Excel;Accounting;Power BI;Financial Analysis | V23: 3 | W23: 13 | X23: =IF(E23="","Missing Email","Available") -> Available | Y23: =IF(U23="","Missing Skills","Available") -> Available | Z23: =IF(T23="","Missing Education","Available") -> Available | AA23: =IF(W23="","Missing Leave Balance","Available") -> Available | AB23: =TRIM(B23&" "&C23) -> Neha Gupta | AC23: =ROUND(N23*O23/100,0) -> 4560 | AD23: =IF(N23>=90000,"High",IF(N23>=60000,"Medium","Low")) -> Low | AE23: =IF(M23>=8,"Senior",IF(M23>=5,"Mid-Level","Junior")) -> Mid-Level | AF23: =IF(Q23>=90,"Top Performer",IF(Q23>=75,"Meets Expectations","Needs Improvement")) -> Meets Expectations
A24: 1023 | B24: Vishnu | C24: Menon | D24: Vishnu Menon | E24: vishnu.menon@example.com | F24: IT | G24: Database Administrator | H24: Kochi | I24: Kerala | J24: Hybrid | K24: Full-Time | L24: 2017 | M24: 9 | N24: 84000 | O24: 12 | P24: 10080 | Q24: 88 | R24: Good | S24: Active | T24: B.Tech | U24: Python;SQL;Cloud;Git;Spark | V24: 6 | W24: 9 | X24: =IF(E24="","Missing Email","Available") -> Available | Y24: =IF(U24="","Missing Skills","Available") -> Available | Z24: =IF(T24="","Missing Education","Available") -> Available | AA24: =IF(W24="","Missing Leave Balance","Available") -> Available | AB24: =TRIM(B24&" "&C24) -> Vishnu Menon | AC24: =ROUND(N24*O24/100,0) -> 10080 | AD24: =IF(N24>=90000,"High",IF(N24>=60000,"Medium","Low")) -> Medium | AE24: =IF(M24>=8,"Senior",IF(M24>=5,"Mid-Level","Junior")) -> Senior | AF24: =IF(Q24>=90,"Top Performer",IF(Q24>=75,"Meets Expectations","Needs Improvement")) -> Meets Expectations
A25: 1024 | B25: Pooja | C25: Patel | D25: Pooja Patel | E25: pooja.patel@example.com | F25: Sales | G25: Sales Executive | H25: Ahmedabad | I25: Gujarat | J25: Office | K25: Full-Time | L25: 2023 | M25: 3 | N25: 46000 | O25: 5 | P25: 2300 | Q25: 71 | R25: Average | S25: Active | T25: MBA | U25: CRM;Negotiation;Excel;Communication | V25: 2 | W25: 16 | X25: =IF(E25="","Missing Email","Available") -> Available | Y25: =IF(U25="","Missing Skills","Available") -> Available | Z25: =IF(T25="","Missing Education","Available") -> Available | AA25: =IF(W25="","Missing Leave Balance","Available") -> Available | AB25: =TRIM(B25&" "&C25) -> Pooja Patel | AC25: =ROUND(N25*O25/100,0) -> 2300 | AD25: =IF(N25>=90000,"High",IF(N25>=60000,"Medium","Low")) -> Low | AE25: =IF(M25>=8,"Senior",IF(M25>=5,"Mid-Level","Junior")) -> Junior | AF25: =IF(Q25>=90,"Top Performer",IF(Q25>=75,"Meets Expectations","Needs Improvement")) -> Needs Improvement
A26: 1025 | B26: Harish | C26: Kumar | D26: Harish Kumar | E26: harish.kumar@example.com | F26: Operations | G26: Business Analyst | H26: Pune | I26: Maharashtra | J26: Hybrid | K26: Full-Time | L26: 2020 | M26: 6 | N26: 67000 | O26: 12 | P26: 8040 | Q26: 85 | R26: Good | S26: Active | U26: Excel;SQL;Power BI;Process Management | V26: 5 | W26: 10 | X26: =IF(E26="","Missing Email","Available") -> Available | Y26: =IF(U26="","Missing Skills","Available") -> Available | Z26: =IF(T26="","Missing Education","Available") -> Missing Education | AA26: =IF(W26="","Missing Leave Balance","Available") -> Available | AB26: =TRIM(B26&" "&C26) -> Harish Kumar | AC26: =ROUND(N26*O26/100,0) -> 8040 | AD26: =IF(N26>=90000,"High",IF(N26>=60000,"Medium","Low")) -> Medium | AE26: =IF(M26>=8,"Senior",IF(M26>=5,"Mid-Level","Junior")) -> Mid-Level | AF26: =IF(Q26>=90,"Top Performer",IF(Q26>=75,"Meets Expectations","Needs Improvement")) -> Meets Expectations
A27: 1026 | B27: Keerthi | C27: Ramesh | D27: Keerthi Ramesh | E27: keerthi.ramesh@example.com | F27: IT | G27: Machine Learning Engineer | H27: Bengaluru | I27: Karnataka | J27: Remote | K27: Full-Time | L27: 2019 | M27: 7 | N27: 98000 | O27: 15 | P27: 14700 | Q27: 97 | R27: Excellent | S27: Active | T27: B.Tech | U27: Python;SQL;Cloud;Git;Spark | V27: 8 | W27: 6 | X27: =IF(E27="","Missing Email","Available") -> Available | Y27: =IF(U27="","Missing Skills","Available") -> Available | Z27: =IF(T27="","Missing Education","Available") -> Available | AA27: =IF(W27="","Missing Leave Balance","Available") -> Available | AB27: =TRIM(B27&" "&C27) -> Keerthi Ramesh | AC27: =ROUND(N27*O27/100,0) -> 14700 | AD27: =IF(N27>=90000,"High",IF(N27>=60000,"Medium","Low")) -> High | AE27: =IF(M27>=8,"Senior",IF(M27>=5,"Mid-Level","Junior")) -> Mid-Level | AF27: =IF(Q27>=90,"Top Performer",IF(Q27>=75,"Meets Expectations","Needs Improvement")) -> Top Performer
A28: 1027 | B28: Sanjay | C28: Das | D28: Sanjay Das | E28: sanjay.das@example.com | F28: Finance | G28: Senior Financial Analyst | H28: Kolkata | I28: West Bengal | J28: Hybrid | K28: Full-Time | L28: 2018 | M28: 8 | N28: 79000 | O28: 12 | P28: 9480 | Q28: 86 | R28: Good | S28: Active | T28: M.Com | U28: Excel;Accounting;Power BI;Financial Analysis | V28: 4 | W28: 12 | X28: =IF(E28="","Missing Email","Available") -> Available | Y28: =IF(U28="","Missing Skills","Available") -> Available | Z28: =IF(T28="","Missing Education","Available") -> Available | AA28: =IF(W28="","Missing Leave Balance","Available") -> Available | AB28: =TRIM(B28&" "&C28) -> Sanjay Das | AC28: =ROUND(N28*O28/100,0) -> 9480 | AD28: =IF(N28>=90000,"High",IF(N28>=60000,"Medium","Low")) -> Medium | AE28: =IF(M28>=8,"Senior",IF(M28>=5,"Mid-Level","Junior")) -> Senior | AF28: =IF(Q28>=90,"Top Performer",IF(Q28>=75,"Meets Expectations","Needs Improvement")) -> Meets Expectations
A29: 1028 | B29: Maya | C29: Thomas | D29: Maya Thomas | E29: maya.thomas@example.com | F29: HR | G29: Talent Acquisition Specialist | H29: Kochi | I29: Kerala | J29: Hybrid | K29: Full-Time | L29: 2020 | M29: 6 | N29: 61000 | O29: 12 | P29: 7320 | Q29: 90 | R29: Excellent | S29: Active | T29: MBA | U29: Recruitment;Excel;HRIS;Communication | V29: 5 | W29: 8 | X29: =IF(E29="","Missing Email","Available") -> Available | Y29: =IF(U29="","Missing Skills","Available") -> Available | Z29: =IF(T29="","Missing Education","Available") -> Available | AA29: =IF(W29="","Missing Leave Balance","Available") -> Available | AB29: =TRIM(B29&" "&C29) -> Maya Thomas | AC29: =ROUND(N29*O29/100,0) -> 7320 | AD29: =IF(N29>=90000,"High",IF(N29>=60000,"Medium","Low")) -> Medium | AE29: =IF(M29>=8,"Senior",IF(M29>=5,"Mid-Level","Junior")) -> Mid-Level | AF29: =IF(Q29>=90,"Top Performer",IF(Q29>=75,"Meets Expectations","Needs Improvement")) -> Top Performer
A30: 1029 | B30: Ajay | C30: Rajan | D30: Ajay Rajan | E30: ajay.rajan@example.com | F30: IT | G30: Full Stack Developer | H30: Chennai | I30: Tamil Nadu | J30: Office | K30: Full-Time | L30: 2021 | M30: 5 | N30: 73000 | O30: 8 | P30: 5840 | Q30: 80 | R30: Good | S30: Active | T30: B.Tech | U30: Python;SQL;Cloud;Git;Spark | V30: 4 | W30: 14 | X30: =IF(E30="","Missing Email","Available") -> Available | Y30: =IF(U30="","Missing Skills","Available") -> Available | Z30: =IF(T30="","Missing Education","Available") -> Available | AA30: =IF(W30="","Missing Leave Balance","Available") -> Available | AB30: =TRIM(B30&" "&C30) -> Ajay Rajan | AC30: =ROUND(N30*O30/100,0) -> 5840 | AD30: =IF(N30>=90000,"High",IF(N30>=60000,"Medium","Low")) -> Medium | AE30: =IF(M30>=8,"Senior",IF(M30>=5,"Mid-Level","Junior")) -> Mid-Level | AF30: =IF(Q30>=90,"Top Performer",IF(Q30>=75,"Meets Expectations","Needs Improvement")) -> Meets Expectations
A31: 1030 | B31: Roshini | C31: Paul | D31: Roshini Paul | E31: roshini.paul@example.com | F31: Marketing | G31: Content Strategist | H31: Kochi | I31: Kerala | J31: Remote | K31: Full-Time | L31: 2022 | M31: 4 | N31: 59000 | O31: 12 | P31: 7080 | Q31: 87 | R31: Good | S31: Active | T31: MBA | U31: SEO;Google Analytics;Content;Social Media | V31: 3 | W31: 11 | X31: =IF(E31="","Missing Email","Available") -> Available | Y31: =IF(U31="","Missing Skills","Available") -> Available | Z31: =IF(T31="","Missing Education","Available") -> Available | AA31: =IF(W31="","Missing Leave Balance","Available") -> Available | AB31: =TRIM(B31&" "&C31) -> Roshini Paul | AC31: =ROUND(N31*O31/100,0) -> 7080 | AD31: =IF(N31>=90000,"High",IF(N31>=60000,"Medium","Low")) -> Low | AE31: =IF(M31>=8,"Senior",IF(M31>=5,"Mid-Level","Junior")) -> Junior | AF31: =IF(Q31>=90,"Top Performer",IF(Q31>=75,"Meets Expectations","Needs Improvement")) -> Meets Expectations
A32: 1031 | B32: Bharath | C32: Rao | D32: Bharath Rao | E32: bharath.rao@example.com | F32: IT | G32: Cloud Architect | H32: Hyderabad | I32: Telangana | J32: Hybrid | K32: Full-Time | L32: 2016 | M32: 10 | N32: 125000 | O32: 15 | P32: 18750 | Q32: 95 | R32: Excellent | S32: Active | T32: B.Tech | U32: Python;SQL;Cloud;Git;Spark | V32: 9 | W32: 7 | X32: =IF(E32="","Missing Email","Available") -> Available | Y32: =IF(U32="","Missing Skills","Available") -> Available | Z32: =IF(T32="","Missing Education","Available") -> Available | AA32: =IF(W32="","Missing Leave Balance","Available") -> Available | AB32: =TRIM(B32&" "&C32) -> Bharath Rao | AC32: =ROUND(N32*O32/100,0) -> 18750 | AD32: =IF(N32>=90000,"High",IF(N32>=60000,"Medium","Low")) -> High | AE32: =IF(M32>=8,"Senior",IF(M32>=5,"Mid-Level","Junior")) -> Senior | AF32: =IF(Q32>=90,"Top Performer",IF(Q32>=75,"Meets Expectations","Needs Improvement")) -> Top Performer
A33: 1032 | B33: Ishita | C33: Roy | D33: Ishita Roy | E33: ishita.roy@example.com | F33: Finance | G33: Financial Analyst | H33: Kolkata | I33: West Bengal | J33: Office | K33: Full-Time | L33: 2022 | M33: 4 | N33: 60000 | O33: 8 | P33: 4800 | Q33: 78 | R33: Average | S33: Active | T33: M.Com | U33: Excel;Accounting;Power BI;Financial Analysis | V33: 3 | W33: 15 | X33: =IF(E33="","Missing Email","Available") -> Available | Y33: =IF(U33="","Missing Skills","Available") -> Available | Z33: =IF(T33="","Missing Education","Available") -> Available | AA33: =IF(W33="","Missing Leave Balance","Available") -> Available | AB33: =TRIM(B33&" "&C33) -> Ishita Roy | AC33: =ROUND(N33*O33/100,0) -> 4800 | AD33: =IF(N33>=90000,"High",IF(N33>=60000,"Medium","Low")) -> Medium | AE33: =IF(M33>=8,"Senior",IF(M33>=5,"Mid-Level","Junior")) -> Junior | AF33: =IF(Q33>=90,"Top Performer",IF(Q33>=75,"Meets Expectations","Needs Improvement")) -> Meets Expectations
A34: 1033 | B34: Naveen | C34: Kumar | D34: Naveen Kumar | E34: naveen.kumar@example.com | F34: Sales | G34: Regional Sales Manager | H34: Pune | I34: Maharashtra | J34: Hybrid | K34: Full-Time | L34: 2017 | M34: 9 | N34: 98000 | O34: 15 | P34: 14700 | Q34: 93 | R34: Excellent | S34: Active | T34: MBA | U34: CRM;Negotiation;Excel;Communication | V34: 7 | W34: 9 | X34: =IF(E34="","Missing Email","Available") -> Available | Y34: =IF(U34="","Missing Skills","Available") -> Available | Z34: =IF(T34="","Missing Education","Available") -> Available | AA34: =IF(W34="","Missing Leave Balance","Available") -> Available | AB34: =TRIM(B34&" "&C34) -> Naveen Kumar | AC34: =ROUND(N34*O34/100,0) -> 14700 | AD34: =IF(N34>=90000,"High",IF(N34>=60000,"Medium","Low")) -> High | AE34: =IF(M34>=8,"Senior",IF(M34>=5,"Mid-Level","Junior")) -> Senior | AF34: =IF(Q34>=90,"Top Performer",IF(Q34>=75,"Meets Expectations","Needs Improvement")) -> Top Performer
A35: 1034 | B35: Harini | C35: S | D35: Harini S | E35: harini.s@example.com | F35: IT | G35: QA Engineer | H35: Chennai | I35: Tamil Nadu | J35: Office | K35: Full-Time | L35: 2023 | M35: 3 | N35: 52000 | O35: 8 | P35: 4160 | Q35: 75 | R35: Average | S35: Active | T35: B.Tech | U35: Python;SQL;Cloud;Git;Spark | V35: 2 | W35: 18 | X35: =IF(E35="","Missing Email","Available") -> Available | Y35: =IF(U35="","Missing Skills","Available") -> Available | Z35: =IF(T35="","Missing Education","Available") -> Available | AA35: =IF(W35="","Missing Leave Balance","Available") -> Available | AB35: =TRIM(B35&" "&C35) -> Harini S | AC35: =ROUND(N35*O35/100,0) -> 4160 | AD35: =IF(N35>=90000,"High",IF(N35>=60000,"Medium","Low")) -> Low | AE35: =IF(M35>=8,"Senior",IF(M35>=5,"Mid-Level","Junior")) -> Junior | AF35: =IF(Q35>=90,"Top Performer",IF(Q35>=75,"Meets Expectations","Needs Improvement")) -> Meets Expectations
A36: 1035 | B36: Mohan | C36: Raj | D36: Mohan Raj | E36: mohan.raj@example.com | F36: Operations | G36: Supply Chain Analyst | H36: Coimbatore | I36: Tamil Nadu | J36: Hybrid | K36: Full-Time | L36: 2021 | M36: 5 | N36: 62000 | O36: 8 | P36: 4960 | Q36: 83 | R36: Good | S36: Active | T36: MBA | U36: Excel;SQL;Power BI;Process Management | V36: 4 | X36: =IF(E36="","Missing Email","Available") -> Available | Y36: =IF(U36="","Missing Skills","Available") -> Available | Z36: =IF(T36="","Missing Education","Available") -> Available | AA36: =IF(W36="","Missing Leave Balance","Available") -> Missing Leave Balance | AB36: =TRIM(B36&" "&C36) -> Mohan Raj | AC36: =ROUND(N36*O36/100,0) -> 4960 | AD36: =IF(N36>=90000,"High",IF(N36>=60000,"Medium","Low")) -> Medium | AE36: =IF(M36>=8,"Senior",IF(M36>=5,"Mid-Level","Junior")) -> Mid-Level | AF36: =IF(Q36>=90,"Top Performer",IF(Q36>=75,"Meets Expectations","Needs Improvement")) -> Meets Expectations
A37: 1036 | B37: Aparna | C37: Krish | D37: Aparna Krish | E37: aparna.krish@example.com | F37: HR | G37: Learning Specialist | H37: Bengaluru | I37: Karnataka | J37: Remote | K37: Full-Time | L37: 2022 | M37: 4 | N37: 56000 | O37: 12 | P37: 6720 | Q37: 88 | R37: Good | S37: Active | T37: MBA | U37: Recruitment;Excel;HRIS;Communication | V37: 3 | W37: 10 | X37: =IF(E37="","Missing Email","Available") -> Available | Y37: =IF(U37="","Missing Skills","Available") -> Available | Z37: =IF(T37="","Missing Education","Available") -> Available | AA37: =IF(W37="","Missing Leave Balance","Available") -> Available | AB37: =TRIM(B37&" "&C37) -> Aparna Krish | AC37: =ROUND(N37*O37/100,0) -> 6720 | AD37: =IF(N37>=90000,"High",IF(N37>=60000,"Medium","Low")) -> Low | AE37: =IF(M37>=8,"Senior",IF(M37>=5,"Mid-Level","Junior")) -> Junior | AF37: =IF(Q37>=90,"Top Performer",IF(Q37>=75,"Meets Expectations","Needs Improvement")) -> Meets Expectations
A38: 1037 | B38: Dinesh | C38: Yadav | D38: Dinesh Yadav | E38: dinesh.yadav@example.com | F38: IT | G38: Network Engineer | H38: Delhi | I38: Delhi | J38: Office | K38: Full-Time | L38: 2019 | M38: 7 | N38: 72000 | O38: 8 | P38: 5760 | Q38: 84 | R38: Good | S38: Active | T38: B.Tech | U38: Python;SQL;Cloud;Git;Spark | V38: 5 | W38: 12 | X38: =IF(E38="","Missing Email","Available") -> Available | Y38: =IF(U38="","Missing Skills","Available") -> Available | Z38: =IF(T38="","Missing Education","Available") -> Available | AA38: =IF(W38="","Missing Leave Balance","Available") -> Available | AB38: =TRIM(B38&" "&C38) -> Dinesh Yadav | AC38: =ROUND(N38*O38/100,0) -> 5760 | AD38: =IF(N38>=90000,"High",IF(N38>=60000,"Medium","Low")) -> Medium | AE38: =IF(M38>=8,"Senior",IF(M38>=5,"Mid-Level","Junior")) -> Mid-Level | AF38: =IF(Q38>=90,"Top Performer",IF(Q38>=75,"Meets Expectations","Needs Improvement")) -> Meets Expectations
A39: 1038 | B39: Sangeetha | C39: M | D39: Sangeetha M | E39: sangeetha.m@example.com | F39: Marketing | G39: Marketing Manager | H39: Bengaluru | I39: Karnataka | J39: Hybrid | K39: Full-Time | L39: 2018 | M39: 8 | N39: 88000 | O39: 15 | P39: 13200 | Q39: 92 | R39: Excellent | S39: Active | T39: MBA | U39: SEO;Google Analytics;Content;Social Media | V39: 6 | W39: 8 | X39: =IF(E39="","Missing Email","Available") -> Available | Y39: =IF(U39="","Missing Skills","Available") -> Available | Z39: =IF(T39="","Missing Education","Available") -> Available | AA39: =IF(W39="","Missing Leave Balance","Available") -> Available | AB39: =TRIM(B39&" "&C39) -> Sangeetha M | AC39: =ROUND(N39*O39/100,0) -> 13200 | AD39: =IF(N39>=90000,"High",IF(N39>=60000,"Medium","Low")) -> Medium | AE39: =IF(M39>=8,"Senior",IF(M39>=5,"Mid-Level","Junior")) -> Senior | AF39: =IF(Q39>=90,"Top Performer",IF(Q39>=75,"Meets Expectations","Needs Improvement")) -> Top Performer
A40: 1039 | B40: Prakash | C40: N | D40: Prakash N | E40: prakash.n@example.com | F40: IT | G40: Data Analyst | H40: Chennai | I40: Tamil Nadu | J40: Hybrid | K40: Full-Time | L40: 2023 | M40: 3 | N40: 56000 | O40: 12 | P40: 6720 | Q40: 86 | R40: Good | S40: Active | T40: B.Tech | U40: Python;SQL;Cloud;Git;Spark | V40: 3 | W40: 15 | X40: =IF(E40="","Missing Email","Available") -> Available | Y40: =IF(U40="","Missing Skills","Available") -> Available | Z40: =IF(T40="","Missing Education","Available") -> Available | AA40: =IF(W40="","Missing Leave Balance","Available") -> Available | AB40: =TRIM(B40&" "&C40) -> Prakash N | AC40: =ROUND(N40*O40/100,0) -> 6720 | AD40: =IF(N40>=90000,"High",IF(N40>=60000,"Medium","Low")) -> Low | AE40: =IF(M40>=8,"Senior",IF(M40>=5,"Mid-Level","Junior")) -> Junior | AF40: =IF(Q40>=90,"Top Performer",IF(Q40>=75,"Meets Expectations","Needs Improvement")) -> Meets Expectations
...

Sheet Pivot_Analysis
A3: Department | B3: Count of Employee_ID | E3: Department | F3: Sum of Annual_Salary
A4: Finance | B4: 8 | E4: Finance | F4: 572000
A5: HR | B5: 6 | E5: HR | F5: 377000
A6: IT | B6: 18 | E6: IT | F6: 1435000
A7: Marketing | B7: 5 | E7: Marketing | F7: 351000
A8: Operations | B8: 6 | E8: Operations | F8: 376000
A9: Sales | B9: 7 | E9: Sales | F9: 450000
A10: Grand Total | B10: 50 | E10: Grand Total | F10: 3561000
A15: Department | B15: Sum of Bonus_Amount | E15: Performance_Rating | F15: Count of Employee_ID
A16: Finance | B16: 61580 | E16: Average | F16: 9
A17: HR | B17: 43490 | E17: Excellent | F17: 18
A18: IT | B18: 183910 | E18: Good | F18: 22
A19: Marketing | B19: 42560 | E19: Needs Improvement | F19: 1
A20: Operations | B20: 37030 | E20: Grand Total | F20: 50
A21: Sales | B21: 45240
A22: Grand Total | B22: 413810
A27: Work_Mode | B27: Count of Employee_ID | E27: State | F27: Count of Employee_ID
A28: Hybrid | B28: 23 | E28: Delhi | F28: 3
A29: Office | B29: 17 | E29: Gujarat | F29: 2
A30: Remote | B30: 10 | E30: Karnataka | F30: 9
A31: Grand Total | B31: 50 | E31: Kerala | F31: 5
E32: Maharashtra | F32: 7
E33: Tamil Nadu | F33: 15
E34: Telangana | F34: 7
E35: West Bengal | F35: 2
E36: Grand Total | F36: 50
A39: Joining_Year | B39: Count of Employee_ID | E39: Experience_Band | F39: Count of Employee_ID
A40: 2016 | B40: 4 | E40: Junior | F40: 14
A41: 2017 | B41: 5 | E41: Mid-Level | F41: 21
A42: 2018 | B42: 6 | E42: Senior | F42: 15
A43: 2019 | B43: 7 | E43: Grand Total | F43: 50
A44: 2020 | B44: 7
A45: 2021 | B45: 7
A46: 2022 | B46: 6
A47: 2023 | B47: 5
A48: 2024 | B48: 3
A49: Grand Total | B49: 50
A51: Salary_Band | B51: Count of Employee_ID
A52: High | B52: 8
A53: Low | B53: 15
...

Sheet Dashboard_1
A1: EMPLOYEE OVERVIEW DASHBOARD
A2: TOTAL EMPLOYEES | D2: TOTAL ANNUAL SALARY | G2: AVERAGE ANNUAL SALARY | J2: TOTAL PROJECTS
A3: =COUNTA(Clean_Data!A2:A51) -> 50 | D3: =SUM(Clean_Data!N2:N51) -> 3561000 | G3: =AVERAGE(Clean_Data!N2:N51) -> 71220 | J3: =SUM(Clean_Data!V2:V51) -> 235

Sheet Dashboard_2
A1: SALARY & COMPENSATION DASHBOARD
A2: TOTAL ANNUAL SALARY | D2: AVERAGE ANNUAL SALARY | G2: HIGHEST ANNUAL SALARY | J2: TOTAL BONUS AMOUNT
A3: =SUM(Clean_Data!N2:N51) -> 3561000 | D3: =AVERAGE(Clean_Data!N2:N51) -> 71220 | G3: =MAX(Clean_Data!N2:N51) -> 125000 | J3: =SUM(Clean_Data!P2:P51) -> 413810

Sheet Dashboard_3
A1: EMPLOYEE PERFORMANCE DASHBOARD
A2: AVERAGE PERFORMANCE SCORE | D2: TOP PERFORMANCE SCORE | G2: EMPLOYEES MEETING TARGET | J2: TOTAL EMPLOYEES
A3: =AVERAGE(Clean_Data!Q2:Q51) -> 85.94 | D3: =MAX(Clean_Data!Q2:Q51) -> 97 | G3: =COUNTIF(Clean_Data!Q2:Q51,">=80") -> 40 | J3: =COUNTA(Clean_Data!A2:A51) -> 50

Sheet Dashboard_4
A1: WORKFORCE & EXPERIENCE DASHBOARD
A2: Total Employees | D2: Average Experience | G2: Active Employees | J2: Total Departments
A3: =COUNTA(Clean_Data!A2:A51) -> 50 | D3: =AVERAGE(Clean_Data!M2:M51) -> 6.08 | G3: =COUNTIF(Clean_Data!S2:S51,"Active") -> 50 | J3: =COUNTA(Pivot_Analysis!A4:A12) -> 7
